WARNING 2020-11-28 09:57:25,096 Not Found: /static/admin/css/fonts.css log 7 140610674378560
WARNING 2020-11-28 09:57:25,302 Not Found: /favicon.ico log 7 140610674378560
INFO 2020-11-28 10:14:59,118 Watching for file changes with StatReloader autoreload 7518 4528500224
INFO 2020-11-28 10:16:41,695 Watching for file changes with StatReloader autoreload 7547 4429671936
INFO 2020-11-28 10:18:28,087 Watching for file changes with StatReloader autoreload 7730 4534443520
INFO 2020-11-28 10:20:50,720 Watching for file changes with StatReloader autoreload 8016 4703243776
WARNING 2020-11-28 10:21:19,015 Not Found: /static/admin/css/fonts.css log 8 140424340420416
WARNING 2020-11-28 10:21:23,624 Not Found: /static/admin/css/fonts.css log 8 140424340420416
WARNING 2020-11-28 10:21:24,802 Not Found: /static/admin/css/base.css log 8 140424340420416
WARNING 2020-11-28 10:21:24,825 Not Found: /static/admin/css/nav_sidebar.css log 8 140424340420416
WARNING 2020-11-28 10:21:24,848 Not Found: /static/admin/js/nav_sidebar.js log 8 140424340420416
WARNING 2020-11-28 10:21:24,875 Not Found: /static/admin/css/login.css log 8 140424340420416
WARNING 2020-11-28 10:21:24,902 Not Found: /static/admin/css/responsive.css log 8 140424340420416
WARNING 2020-11-28 10:21:25,055 Not Found: /favicon.ico log 8 140424340420416
INFO 2020-11-28 10:22:12,845 Watching for file changes with StatReloader autoreload 8079 4352536064
INFO 2020-11-28 10:22:18,586 "GET / HTTP/1.1" 200 16351 basehttp 8079 123145427427328
INFO 2020-11-28 10:22:18,600 "GET /static/admin/css/fonts.css HTTP/1.1" 200 423 basehttp 8079 123145427427328
INFO 2020-11-28 10:22:18,639 "GET /static/admin/fonts/Roboto-Light-webfont.woff HTTP/1.1" 200 85692 basehttp 8079 123145427427328
INFO 2020-11-28 10:22:18,645 "GET /static/admin/fonts/Roboto-Bold-webfont.woff HTTP/1.1" 200 86184 basehttp 8079 123145461006336
INFO 2020-11-28 10:22:18,645 "GET /static/admin/fonts/Roboto-Regular-webfont.woff HTTP/1.1" 200 85876 basehttp 8079 123145477795840
WARNING 2020-11-28 10:22:18,653 Not Found: /favicon.ico log 8079 123145444216832
WARNING 2020-11-28 10:22:18,655 "GET /favicon.ico HTTP/1.1" 404 1978 basehttp 8079 123145444216832
WARNING 2020-11-28 10:22:18,725 Not Found: /apple-touch-icon-precomposed.png log 8079 123145494585344
WARNING 2020-11-28 10:22:18,725 "GET /apple-touch-icon-precomposed.png HTTP/1.1" 404 2041 basehttp 8079 123145494585344
WARNING 2020-11-28 10:22:18,736 Not Found: /apple-touch-icon.png log 8079 123145494585344
WARNING 2020-11-28 10:22:18,737 "GET /apple-touch-icon.png HTTP/1.1" 404 2005 basehttp 8079 123145494585344
INFO 2020-11-28 10:22:23,147 "GET / HTTP/1.1" 200 16351 basehttp 8079 123145427427328
WARNING 2020-11-28 10:22:23,162 Not Found: /favicon.ico log 8079 123145444216832
WARNING 2020-11-28 10:22:23,162 "GET /favicon.ico HTTP/1.1" 404 1978 basehttp 8079 123145444216832
INFO 2020-11-28 10:22:23,382 "GET /admin/ HTTP/1.1" 302 0 basehttp 8079 123145427427328
INFO 2020-11-28 10:22:23,475 "GET /admin/login/?next=/admin/ HTTP/1.1" 200 2194 basehttp 8079 123145427427328
INFO 2020-11-28 10:22:23,488 "GET /static/admin/css/base.css HTTP/1.1" 200 16307 basehttp 8079 123145444216832
INFO 2020-11-28 10:22:23,490 "GET /static/admin/css/nav_sidebar.css HTTP/1.1" 200 2138 basehttp 8079 123145427427328
INFO 2020-11-28 10:22:23,493 "GET /static/admin/css/responsive.css HTTP/1.1" 200 18339 basehttp 8079 123145511374848
INFO 2020-11-28 10:22:23,493 "GET /static/admin/js/nav_sidebar.js HTTP/1.1" 200 1360 basehttp 8079 123145461006336
INFO 2020-11-28 10:22:23,494 "GET /static/admin/css/login.css HTTP/1.1" 200 1185 basehttp 8079 123145528164352
WARNING 2020-11-28 12:04:31,102 Not Found: /static/admin/css/fonts.css log 8 140245526509376
WARNING 2020-11-28 12:04:36,343 Not Found: /static/admin/css/fonts.css log 8 140245526509376
WARNING 2020-11-28 12:04:40,491 Not Found: /static/admin/css/fonts.css log 8 140245526509376
WARNING 2020-11-28 12:04:40,934 Not Found: /static/admin/css/base.css log 8 140245526509376
WARNING 2020-11-28 12:04:40,960 Not Found: /static/admin/css/nav_sidebar.css log 8 140245526509376
WARNING 2020-11-28 12:04:40,983 Not Found: /static/admin/js/nav_sidebar.js log 8 140245526509376
WARNING 2020-11-28 12:04:41,006 Not Found: /static/admin/css/responsive.css log 8 140245526509376
WARNING 2020-11-28 12:04:41,028 Not Found: /static/admin/css/login.css log 8 140245526509376
WARNING 2020-11-28 12:04:41,586 Not Found: /static/admin/css/nav_sidebar.css log 8 140245526509376
WARNING 2020-11-28 12:04:41,617 Not Found: /static/admin/js/nav_sidebar.js log 8 140245526509376
WARNING 2020-11-28 12:04:41,651 Not Found: /static/admin/css/login.css log 8 140245526509376
WARNING 2020-11-28 12:04:41,688 Not Found: /static/admin/css/base.css log 8 140245526509376
WARNING 2020-11-28 12:04:41,719 Not Found: /static/admin/css/responsive.css log 8 140245526509376
ERROR 2020-11-28 12:04:52,046 Internal Server Error: /admin/login/ log 8 140245526509376
Traceback (most recent call last):
  File "/usr/local/lib/python3.8/site-packages/django/db/backends/base/base.py", line 219, in ensure_connection
    self.connect()
  File "/usr/local/lib/python3.8/site-packages/django/utils/asyncio.py", line 26, in inner
    return func(*args, **kwargs)
  File "/usr/local/lib/python3.8/site-packages/django/db/backends/base/base.py", line 200, in connect
    self.connection = self.get_new_connection(conn_params)
  File "/usr/local/lib/python3.8/site-packages/django/utils/asyncio.py", line 26, in inner
    return func(*args, **kwargs)
  File "/usr/local/lib/python3.8/site-packages/django/db/backends/postgresql/base.py", line 187, in get_new_connection
    connection = Database.connect(**conn_params)
  File "/usr/local/lib/python3.8/site-packages/psycopg2/__init__.py", line 126, in connect
    conn = _connect(dsn, connection_factory=connection_factory, **kwasync)
psycopg2.OperationalError: could not connect to server: Connection refused
	Is the server running on host "127.0.0.1" and accepting
	TCP/IP connections on port 5432?


The above exception was the direct cause of the following exception:

Traceback (most recent call last):
  File "/usr/local/lib/python3.8/site-packages/django/core/handlers/exception.py", line 47, in inner
    response = get_response(request)
  File "/usr/local/lib/python3.8/site-packages/django/core/handlers/base.py", line 179, in _get_response
    response = wrapped_callback(request, *callback_args, **callback_kwargs)
  File "/usr/local/lib/python3.8/site-packages/django/views/decorators/cache.py", line 44, in _wrapped_view_func
    response = view_func(request, *args, **kwargs)
  File "/usr/local/lib/python3.8/site-packages/django/contrib/admin/sites.py", line 410, in login
    return LoginView.as_view(**defaults)(request)
  File "/usr/local/lib/python3.8/site-packages/django/views/generic/base.py", line 70, in view
    return self.dispatch(request, *args, **kwargs)
  File "/usr/local/lib/python3.8/site-packages/django/utils/decorators.py", line 43, in _wrapper
    return bound_method(*args, **kwargs)
  File "/usr/local/lib/python3.8/site-packages/django/views/decorators/debug.py", line 89, in sensitive_post_parameters_wrapper
    return view(request, *args, **kwargs)
  File "/usr/local/lib/python3.8/site-packages/django/utils/decorators.py", line 43, in _wrapper
    return bound_method(*args, **kwargs)
  File "/usr/local/lib/python3.8/site-packages/django/utils/decorators.py", line 130, in _wrapped_view
    response = view_func(request, *args, **kwargs)
  File "/usr/local/lib/python3.8/site-packages/django/utils/decorators.py", line 43, in _wrapper
    return bound_method(*args, **kwargs)
  File "/usr/local/lib/python3.8/site-packages/django/views/decorators/cache.py", line 44, in _wrapped_view_func
    response = view_func(request, *args, **kwargs)
  File "/usr/local/lib/python3.8/site-packages/django/contrib/auth/views.py", line 63, in dispatch
    return super().dispatch(request, *args, **kwargs)
  File "/usr/local/lib/python3.8/site-packages/django/views/generic/base.py", line 98, in dispatch
    return handler(request, *args, **kwargs)
  File "/usr/local/lib/python3.8/site-packages/django/views/generic/edit.py", line 141, in post
    if form.is_valid():
  File "/usr/local/lib/python3.8/site-packages/django/forms/forms.py", line 177, in is_valid
    return self.is_bound and not self.errors
  File "/usr/local/lib/python3.8/site-packages/django/forms/forms.py", line 172, in errors
    self.full_clean()
  File "/usr/local/lib/python3.8/site-packages/django/forms/forms.py", line 375, in full_clean
    self._clean_form()
  File "/usr/local/lib/python3.8/site-packages/django/forms/forms.py", line 402, in _clean_form
    cleaned_data = self.clean()
  File "/usr/local/lib/python3.8/site-packages/django/contrib/auth/forms.py", line 215, in clean
    self.user_cache = authenticate(self.request, username=username, password=password)
  File "/usr/local/lib/python3.8/site-packages/django/contrib/auth/__init__.py", line 73, in authenticate
    user = backend.authenticate(request, **credentials)
  File "/usr/local/lib/python3.8/site-packages/django/contrib/auth/backends.py", line 42, in authenticate
    user = UserModel._default_manager.get_by_natural_key(username)
  File "/usr/local/lib/python3.8/site-packages/django/contrib/auth/base_user.py", line 45, in get_by_natural_key
    return self.get(**{self.model.USERNAME_FIELD: username})
  File "/usr/local/lib/python3.8/site-packages/django/db/models/manager.py", line 85, in manager_method
    return getattr(self.get_queryset(), name)(*args, **kwargs)
  File "/usr/local/lib/python3.8/site-packages/django/db/models/query.py", line 425, in get
    num = len(clone)
  File "/usr/local/lib/python3.8/site-packages/django/db/models/query.py", line 269, in __len__
    self._fetch_all()
  File "/usr/local/lib/python3.8/site-packages/django/db/models/query.py", line 1308, in _fetch_all
    self._result_cache = list(self._iterable_class(self))
  File "/usr/local/lib/python3.8/site-packages/django/db/models/query.py", line 53, in __iter__
    results = compiler.execute_sql(chunked_fetch=self.chunked_fetch, chunk_size=self.chunk_size)
  File "/usr/local/lib/python3.8/site-packages/django/db/models/sql/compiler.py", line 1154, in execute_sql
    cursor = self.connection.cursor()
  File "/usr/local/lib/python3.8/site-packages/django/utils/asyncio.py", line 26, in inner
    return func(*args, **kwargs)
  File "/usr/local/lib/python3.8/site-packages/django/db/backends/base/base.py", line 259, in cursor
    return self._cursor()
  File "/usr/local/lib/python3.8/site-packages/django/db/backends/base/base.py", line 235, in _cursor
    self.ensure_connection()
  File "/usr/local/lib/python3.8/site-packages/django/utils/asyncio.py", line 26, in inner
    return func(*args, **kwargs)
  File "/usr/local/lib/python3.8/site-packages/django/db/backends/base/base.py", line 219, in ensure_connection
    self.connect()
  File "/usr/local/lib/python3.8/site-packages/django/db/utils.py", line 90, in __exit__
    raise dj_exc_value.with_traceback(traceback) from exc_value
  File "/usr/local/lib/python3.8/site-packages/django/db/backends/base/base.py", line 219, in ensure_connection
    self.connect()
  File "/usr/local/lib/python3.8/site-packages/django/utils/asyncio.py", line 26, in inner
    return func(*args, **kwargs)
  File "/usr/local/lib/python3.8/site-packages/django/db/backends/base/base.py", line 200, in connect
    self.connection = self.get_new_connection(conn_params)
  File "/usr/local/lib/python3.8/site-packages/django/utils/asyncio.py", line 26, in inner
    return func(*args, **kwargs)
  File "/usr/local/lib/python3.8/site-packages/django/db/backends/postgresql/base.py", line 187, in get_new_connection
    connection = Database.connect(**conn_params)
  File "/usr/local/lib/python3.8/site-packages/psycopg2/__init__.py", line 126, in connect
    conn = _connect(dsn, connection_factory=connection_factory, **kwasync)
django.db.utils.OperationalError: could not connect to server: Connection refused
	Is the server running on host "127.0.0.1" and accepting
	TCP/IP connections on port 5432?

WARNING 2020-11-28 12:08:31,387 Not Found: /static/admin/css/fonts.css log 8 140245526509376
WARNING 2020-11-28 12:08:35,758 Not Found: /static/admin/css/fonts.css log 8 140245526509376
WARNING 2020-11-28 12:08:36,338 Not Found: /static/admin/css/base.css log 8 140245526509376
WARNING 2020-11-28 12:08:36,369 Not Found: /static/admin/css/nav_sidebar.css log 8 140245526509376
WARNING 2020-11-28 12:08:36,395 Not Found: /static/admin/js/nav_sidebar.js log 8 140245526509376
WARNING 2020-11-28 12:08:36,419 Not Found: /static/admin/css/login.css log 8 140245526509376
WARNING 2020-11-28 12:08:36,445 Not Found: /static/admin/css/responsive.css log 8 140245526509376
WARNING 2020-11-28 12:08:36,999 Not Found: /static/admin/css/base.css log 8 140245526509376
WARNING 2020-11-28 12:08:37,029 Not Found: /static/admin/js/nav_sidebar.js log 8 140245526509376
WARNING 2020-11-28 12:08:37,050 Not Found: /static/admin/css/nav_sidebar.css log 8 140245526509376
WARNING 2020-11-28 12:08:37,077 Not Found: /static/admin/css/login.css log 8 140245526509376
WARNING 2020-11-28 12:08:37,104 Not Found: /static/admin/css/responsive.css log 8 140245526509376
ERROR 2020-11-28 12:08:41,408 Internal Server Error: /admin/login/ log 8 140245526509376
Traceback (most recent call last):
  File "/usr/local/lib/python3.8/site-packages/django/db/backends/base/base.py", line 219, in ensure_connection
    self.connect()
  File "/usr/local/lib/python3.8/site-packages/django/utils/asyncio.py", line 26, in inner
    return func(*args, **kwargs)
  File "/usr/local/lib/python3.8/site-packages/django/db/backends/base/base.py", line 200, in connect
    self.connection = self.get_new_connection(conn_params)
  File "/usr/local/lib/python3.8/site-packages/django/utils/asyncio.py", line 26, in inner
    return func(*args, **kwargs)
  File "/usr/local/lib/python3.8/site-packages/django/db/backends/postgresql/base.py", line 187, in get_new_connection
    connection = Database.connect(**conn_params)
  File "/usr/local/lib/python3.8/site-packages/psycopg2/__init__.py", line 126, in connect
    conn = _connect(dsn, connection_factory=connection_factory, **kwasync)
psycopg2.OperationalError: could not connect to server: Connection refused
	Is the server running on host "127.0.0.1" and accepting
	TCP/IP connections on port 5432?


The above exception was the direct cause of the following exception:

Traceback (most recent call last):
  File "/usr/local/lib/python3.8/site-packages/django/core/handlers/exception.py", line 47, in inner
    response = get_response(request)
  File "/usr/local/lib/python3.8/site-packages/django/core/handlers/base.py", line 179, in _get_response
    response = wrapped_callback(request, *callback_args, **callback_kwargs)
  File "/usr/local/lib/python3.8/site-packages/django/views/decorators/cache.py", line 44, in _wrapped_view_func
    response = view_func(request, *args, **kwargs)
  File "/usr/local/lib/python3.8/site-packages/django/contrib/admin/sites.py", line 410, in login
    return LoginView.as_view(**defaults)(request)
  File "/usr/local/lib/python3.8/site-packages/django/views/generic/base.py", line 70, in view
    return self.dispatch(request, *args, **kwargs)
  File "/usr/local/lib/python3.8/site-packages/django/utils/decorators.py", line 43, in _wrapper
    return bound_method(*args, **kwargs)
  File "/usr/local/lib/python3.8/site-packages/django/views/decorators/debug.py", line 89, in sensitive_post_parameters_wrapper
    return view(request, *args, **kwargs)
  File "/usr/local/lib/python3.8/site-packages/django/utils/decorators.py", line 43, in _wrapper
    return bound_method(*args, **kwargs)
  File "/usr/local/lib/python3.8/site-packages/django/utils/decorators.py", line 130, in _wrapped_view
    response = view_func(request, *args, **kwargs)
  File "/usr/local/lib/python3.8/site-packages/django/utils/decorators.py", line 43, in _wrapper
    return bound_method(*args, **kwargs)
  File "/usr/local/lib/python3.8/site-packages/django/views/decorators/cache.py", line 44, in _wrapped_view_func
    response = view_func(request, *args, **kwargs)
  File "/usr/local/lib/python3.8/site-packages/django/contrib/auth/views.py", line 63, in dispatch
    return super().dispatch(request, *args, **kwargs)
  File "/usr/local/lib/python3.8/site-packages/django/views/generic/base.py", line 98, in dispatch
    return handler(request, *args, **kwargs)
  File "/usr/local/lib/python3.8/site-packages/django/views/generic/edit.py", line 141, in post
    if form.is_valid():
  File "/usr/local/lib/python3.8/site-packages/django/forms/forms.py", line 177, in is_valid
    return self.is_bound and not self.errors
  File "/usr/local/lib/python3.8/site-packages/django/forms/forms.py", line 172, in errors
    self.full_clean()
  File "/usr/local/lib/python3.8/site-packages/django/forms/forms.py", line 375, in full_clean
    self._clean_form()
  File "/usr/local/lib/python3.8/site-packages/django/forms/forms.py", line 402, in _clean_form
    cleaned_data = self.clean()
  File "/usr/local/lib/python3.8/site-packages/django/contrib/auth/forms.py", line 215, in clean
    self.user_cache = authenticate(self.request, username=username, password=password)
  File "/usr/local/lib/python3.8/site-packages/django/contrib/auth/__init__.py", line 73, in authenticate
    user = backend.authenticate(request, **credentials)
  File "/usr/local/lib/python3.8/site-packages/django/contrib/auth/backends.py", line 42, in authenticate
    user = UserModel._default_manager.get_by_natural_key(username)
  File "/usr/local/lib/python3.8/site-packages/django/contrib/auth/base_user.py", line 45, in get_by_natural_key
    return self.get(**{self.model.USERNAME_FIELD: username})
  File "/usr/local/lib/python3.8/site-packages/django/db/models/manager.py", line 85, in manager_method
    return getattr(self.get_queryset(), name)(*args, **kwargs)
  File "/usr/local/lib/python3.8/site-packages/django/db/models/query.py", line 425, in get
    num = len(clone)
  File "/usr/local/lib/python3.8/site-packages/django/db/models/query.py", line 269, in __len__
    self._fetch_all()
  File "/usr/local/lib/python3.8/site-packages/django/db/models/query.py", line 1308, in _fetch_all
    self._result_cache = list(self._iterable_class(self))
  File "/usr/local/lib/python3.8/site-packages/django/db/models/query.py", line 53, in __iter__
    results = compiler.execute_sql(chunked_fetch=self.chunked_fetch, chunk_size=self.chunk_size)
  File "/usr/local/lib/python3.8/site-packages/django/db/models/sql/compiler.py", line 1154, in execute_sql
    cursor = self.connection.cursor()
  File "/usr/local/lib/python3.8/site-packages/django/utils/asyncio.py", line 26, in inner
    return func(*args, **kwargs)
  File "/usr/local/lib/python3.8/site-packages/django/db/backends/base/base.py", line 259, in cursor
    return self._cursor()
  File "/usr/local/lib/python3.8/site-packages/django/db/backends/base/base.py", line 235, in _cursor
    self.ensure_connection()
  File "/usr/local/lib/python3.8/site-packages/django/utils/asyncio.py", line 26, in inner
    return func(*args, **kwargs)
  File "/usr/local/lib/python3.8/site-packages/django/db/backends/base/base.py", line 219, in ensure_connection
    self.connect()
  File "/usr/local/lib/python3.8/site-packages/django/db/utils.py", line 90, in __exit__
    raise dj_exc_value.with_traceback(traceback) from exc_value
  File "/usr/local/lib/python3.8/site-packages/django/db/backends/base/base.py", line 219, in ensure_connection
    self.connect()
  File "/usr/local/lib/python3.8/site-packages/django/utils/asyncio.py", line 26, in inner
    return func(*args, **kwargs)
  File "/usr/local/lib/python3.8/site-packages/django/db/backends/base/base.py", line 200, in connect
    self.connection = self.get_new_connection(conn_params)
  File "/usr/local/lib/python3.8/site-packages/django/utils/asyncio.py", line 26, in inner
    return func(*args, **kwargs)
  File "/usr/local/lib/python3.8/site-packages/django/db/backends/postgresql/base.py", line 187, in get_new_connection
    connection = Database.connect(**conn_params)
  File "/usr/local/lib/python3.8/site-packages/psycopg2/__init__.py", line 126, in connect
    conn = _connect(dsn, connection_factory=connection_factory, **kwasync)
django.db.utils.OperationalError: could not connect to server: Connection refused
	Is the server running on host "127.0.0.1" and accepting
	TCP/IP connections on port 5432?

WARNING 2020-11-28 17:14:40,658 Not Found: /static/admin/css/fonts.css log 7 140055133312832
WARNING 2020-11-28 17:14:44,094 Not Found: /static/admin/css/fonts.css log 7 140055133312832
WARNING 2020-11-28 17:14:44,355 Not Found: /static/admin/css/base.css log 7 140055133312832
WARNING 2020-11-28 17:14:44,374 Not Found: /static/admin/css/nav_sidebar.css log 7 140055133312832
WARNING 2020-11-28 17:14:44,391 Not Found: /static/admin/css/responsive.css log 7 140055133312832
WARNING 2020-11-28 17:14:44,408 Not Found: /static/admin/js/nav_sidebar.js log 7 140055133312832
WARNING 2020-11-28 17:14:44,423 Not Found: /static/admin/css/login.css log 7 140055133312832
WARNING 2020-11-28 17:14:45,048 Not Found: /static/admin/css/base.css log 7 140055133312832
WARNING 2020-11-28 17:14:45,071 Not Found: /static/admin/css/nav_sidebar.css log 7 140055133312832
WARNING 2020-11-28 17:14:45,087 Not Found: /static/admin/css/login.css log 7 140055133312832
WARNING 2020-11-28 17:14:45,104 Not Found: /static/admin/css/responsive.css log 7 140055133312832
WARNING 2020-11-28 17:14:45,122 Not Found: /static/admin/js/nav_sidebar.js log 7 140055133312832
WARNING 2020-11-28 18:06:03,752 Not Found: /static/admin/css/fonts.css log 7 139966520866624
WARNING 2020-11-28 18:06:07,749 Not Found: /static/admin/css/fonts.css log 7 139966520866624
WARNING 2020-11-28 18:06:11,209 Not Found: /static/admin/css/nav_sidebar.css log 7 139966520866624
WARNING 2020-11-28 18:06:11,232 Not Found: /static/admin/css/base.css log 7 139966520866624
WARNING 2020-11-28 18:06:11,258 Not Found: /static/admin/css/login.css log 7 139966520866624
WARNING 2020-11-28 18:06:11,281 Not Found: /static/admin/css/responsive.css log 7 139966520866624
WARNING 2020-11-28 18:06:11,307 Not Found: /static/admin/js/nav_sidebar.js log 7 139966520866624
WARNING 2020-11-28 18:08:27,902 Not Found: /static/admin/css/nav_sidebar.css log 7 140253170005824
WARNING 2020-11-28 18:08:27,918 Not Found: /static/admin/js/nav_sidebar.js log 7 140253170005824
WARNING 2020-11-28 18:08:27,936 Not Found: /static/admin/css/login.css log 7 140253170005824
WARNING 2020-11-28 18:08:27,953 Not Found: /static/admin/css/base.css log 7 140253170005824
WARNING 2020-11-28 18:08:27,973 Not Found: /static/admin/css/responsive.css log 7 140253170005824
WARNING 2020-11-28 18:08:30,982 Not Found: /static/admin/css/nav_sidebar.css log 7 140253170005824
WARNING 2020-11-28 18:08:31,000 Not Found: /static/admin/js/nav_sidebar.js log 7 140253170005824
WARNING 2020-11-28 18:08:31,019 Not Found: /static/admin/css/responsive.css log 7 140253170005824
WARNING 2020-11-28 18:08:31,035 Not Found: /static/admin/css/login.css log 7 140253170005824
WARNING 2020-11-28 18:08:31,053 Not Found: /static/admin/css/base.css log 7 140253170005824
WARNING 2020-11-28 18:08:41,404 Not Found: /static/admin/css/base.css log 7 140253170005824
WARNING 2020-11-28 18:08:41,426 Not Found: /static/admin/css/nav_sidebar.css log 7 140253170005824
WARNING 2020-11-28 18:08:41,442 Not Found: /static/admin/js/nav_sidebar.js log 7 140253170005824
WARNING 2020-11-28 18:08:41,492 Not Found: /static/admin/css/responsive.css log 7 140253170005824
WARNING 2020-11-28 18:08:41,516 Not Found: /static/admin/css/dashboard.css log 7 140253170005824
WARNING 2020-11-28 18:08:41,547 Not Found: /static/admin/css/base.css log 7 140253170005824
WARNING 2020-11-28 18:08:41,567 Not Found: /static/admin/css/nav_sidebar.css log 7 140253170005824
WARNING 2020-11-28 18:08:41,586 Not Found: /static/admin/js/nav_sidebar.js log 7 140253170005824
WARNING 2020-11-28 18:08:41,603 Not Found: /static/admin/css/login.css log 7 140253170005824
WARNING 2020-11-28 18:08:41,631 Not Found: /favicon.ico log 7 140253170005824
WARNING 2020-11-28 18:08:45,283 Not Found: /static/admin/css/base.css log 7 140253170005824
WARNING 2020-11-28 18:08:45,301 Not Found: /static/admin/css/responsive.css log 7 140253170005824
WARNING 2020-11-28 18:08:45,317 Not Found: /static/admin/css/nav_sidebar.css log 7 140253170005824
WARNING 2020-11-28 18:08:45,333 Not Found: /static/admin/js/nav_sidebar.js log 7 140253170005824
WARNING 2020-11-28 18:08:45,350 Not Found: /static/admin/css/dashboard.css log 7 140253170005824
